<?xml version="1.0" encoding="utf-8"?>
<robot name="galileo_mini_description">
  <link name="world" />
  <joint name="floating_base_joint" type="floating">
    <origin xyz="0 0 0" rpy="0 0 0" />
    <parent link="world" />
    <child link="base_link" />
  </joint>
  <link name="base_link">
    <inertial>
      <origin
        xyz="0.03738 -0.0065903 0.0057934"
        rpy="0 0 0" />
      <mass
        value="20.8" />
      <inertia
        ixx="0.131102"
        ixy="0.001924"
        ixz="0.001299"
        iyy="0.407915"
        iyz="0.002595"
        izz="0.476755" />
    </inertial>
    <visual>
      <origin
        xyz="0 0 0"
        rpy="0 0 0" />
      <geometry>
        <mesh
          filename="package://galileo_mini_description/meshes/base_link.STL" />
      </geometry>
      <material
        name="">
        <color
          rgba="0.75294 0.75294 0.75294 1" />
      </material>
    </visual>
    <collision>
      <origin
        xyz="0 0 0"
        rpy="0 0 0" />
      <geometry>
        <box size="0.45 0.25 0.1" />
      </geometry>
    </collision>
  </link>

  <link name="FL_abd_link">
    <inertial>
      <origin
        xyz="0.067568 0.0095934 1.3738E-05"
        rpy="0 0 0" />
      <mass
        value="2.86" />
      <inertia
        ixx="0.004368"
        ixy="0.000362"
        ixz="0.000114"
        iyy="0.007476"
        iyz="0.000035"
        izz="0.006777" />
    </inertial>
    <visual>
      <origin
        xyz="0 0 0"
        rpy="0 0 0" />
      <geometry>
        <mesh
          filename="package://galileo_mini_description/meshes/FL_abd_link.STL" />
      </geometry>
      <material
        name="">
        <color
          rgba="0.75294 0.75294 0.75294 1" />
      </material>
    </visual>
    <collision>
      <origin
        xyz="0.1 0.03325 0"
        rpy="1.5707963 0 0" />
      <geometry>
        <cylinder radius="0.06" length="0.1065" />
      </geometry>
    </collision>
  </link>
  <joint name="FL_abd_joint" type="revolute">
    <origin
      xyz="0.2015 0.08 0"
      rpy="0 0 0" />
    <parent
      link="base_link" />
    <child
      link="FL_abd_link" />
    <axis
      xyz="1 0 0" />
    <limit
      lower="-0.80285"
      upper="0.80285"
      effort="100"
      velocity="21" />
  </joint>

  <link name="FL_hip_link">
    <inertial>
      <origin
        xyz="-0.0090988 -0.0065295 -0.0688"
        rpy="0 0 0" />
      <mass
        value="2.6" />
      <inertia
        ixx="0.016848"
        ixy="-0.000310"
        ixz="0.001116"
        iyy="0.016749"
        iyz="-0.002270"
        izz="0.002088" />
    </inertial>
    <visual>
      <origin
        xyz="0 0 0"
        rpy="0 0 0" />
      <geometry>
        <mesh
          filename="package://galileo_mini_description/meshes/FL_hip_link.STL" />
      </geometry>
      <material
        name="">
        <color
          rgba="0.75294 0.75294 0.75294 1" />
      </material>
    </visual>
    <collision>
      <origin
        xyz="-0.025 0 -0.08"
        rpy="0 0 0" />
      <geometry>
        <box size="0.06 0.035 0.26" />
      </geometry>
    </collision>
  </link>
  <joint name="FL_hip_joint" type="revolute">
    <origin
      xyz="0.1 0.1065 0"
      rpy="0 0 0" />
    <parent
      link="FL_abd_link" />
    <child
      link="FL_hip_link" />
    <axis
      xyz="0 1 0" />
    <limit
      lower="-4.1888"
      upper="1.0472"
      effort="100"
      velocity="21" />
  </joint>
  <link name="FL_knee_link">
    <inertial>
      <origin
        xyz="0.017829 -1.577E-05 -0.099213"
        rpy="0 0 0" />
      <mass
        value="0.314" />
      <inertia
        ixx="0.003733"
        ixy="-0.000000087"
        ixz="-0.0006"
        iyy="0.003882"
        iyz="0.000000838"
        izz="0.000177" />
    </inertial>
    <visual>
      <origin
        xyz="0 0 0"
        rpy="0 0 0" />
      <geometry>
        <mesh
          filename="package://galileo_mini_description/meshes/FL_knee_link.STL" />
      </geometry>
      <material
        name="">
        <color
          rgba="0.75294 0.75294 0.75294 1" />
      </material>
    </visual>
    <collision>
      <origin
        xyz="0.0164695 0 -0.13"
        rpy="0 -0.17453 0" />
      <geometry>
        <box size="0.05 0.03 0.23" />
      </geometry>
    </collision>
  </link>
  <joint name="FL_knee_joint" type="revolute">
    <origin
      xyz="0 0 -0.26"
      rpy="0 0 0" />
    <parent
      link="FL_hip_link" />
    <child
      link="FL_knee_link" />
    <axis
      xyz="0 1 0" />
    <limit
      lower="-2.6965"
      upper="-0.9163"
      effort="150"
      velocity="21" />
  </joint>
  <link name="FL_foot_link">
    <inertial>
      <origin
        xyz="-5.5511E-17 0 0"
        rpy="0 0 0" />
      <mass
        value="0.00020487" />
      <inertia
        ixx="1.096E-09"
        ixy="-2.0392E-56"
        ixz="0"
        iyy="1.096E-09"
        iyz="0"
        izz="1.096E-09" />
    </inertial>
    <visual>
      <origin
        xyz="0 0 0"
        rpy="0 0 0" />
      <geometry>
        <sphere radius="0.030" />
      </geometry>
      <material
        name="">
        <color
          rgba="1 1 1 1" />
      </material>
    </visual>
    <collision>
      <origin
        xyz="0 0 0"
        rpy="0 0 0" />
      <geometry>
        <sphere radius="0.030" />
      </geometry>
    </collision>
  </link>
  <joint name="FL_foot_joint" type="fixed">
    <origin
      xyz="0.032939 0 -0.26149"
      rpy="0 0 0" />
    <parent
      link="FL_knee_link" />
    <child
      link="FL_foot_link" />
    <axis
      xyz="0 0 0" />
  </joint>

  <joint name="FR_abd_joint" type="revolute">
    <origin
      xyz="0.2015 -0.08 0"
      rpy="0 0 0" />
    <parent
      link="base_link" />
    <child
      link="FR_abd_link" />
    <axis
      xyz="1 0 0" />
    <limit
      lower="-0.80285"
      upper="0.80285"
      effort="100"
      velocity="21" />
  </joint>
  <link name="FR_abd_link">
    <inertial>
      <origin
        xyz="0.067568 -0.0091759 -0.00023747"
        rpy="0 0 0" />
      <mass
        value="2.86" />
      <inertia
        ixx="0.004373"
        ixy="-0.000397"
        ixz="-0.000096"
        iyy="0.007483"
        iyz="0.000030"
        izz="0.006775" />
    </inertial>
    <visual>
      <origin
        xyz="0 0 0"
        rpy="0 0 0" />
      <geometry>
        <mesh
          filename="package://galileo_mini_description/meshes/FR_abd_link.STL" />
      </geometry>
      <material
        name="">
        <color
          rgba="0.75294 0.75294 0.75294 1" />
      </material>
    </visual>
    <collision>
      <origin
        xyz="0.1 -0.03325 0"
        rpy="1.5707963 0 0" />
      <geometry>
        <cylinder radius="0.06" length="0.1065" />
      </geometry>
    </collision>
  </link>
  <joint name="FR_hip_joint" type="revolute">
    <origin
      xyz="0.1 -0.10685 0"
      rpy="0 0 0" />
    <parent
      link="FR_abd_link" />
    <child
      link="FR_hip_link" />
    <axis
      xyz="0 1 0" />
    <limit
      lower="-4.1888"
      upper="1.0472"
      effort="100"
      velocity="21" />
  </joint>
  <link name="FR_hip_link">
    <inertial>
      <origin
        xyz="-0.0095338 0.026092 -0.067392"
        rpy="0 0 0" />
      <mass
        value="2.6" />
      <inertia
        ixx="0.016261"
        ixy="0.000284"
        ixz="0.001143"
        iyy="0.016389"
        iyz="0.002508"
        izz="0.002194" />
    </inertial>
    <visual>
      <origin
        xyz="0 0 0"
        rpy="0 0 0" />
      <geometry>
        <mesh
          filename="package://galileo_mini_description/meshes/FR_hip_link.STL" />
      </geometry>
      <material
        name="">
        <color
          rgba="0.75294 0.75294 0.75294 1" />
      </material>
    </visual>
    <collision>
      <origin
        xyz="-0.025 0 -0.08"
        rpy="0 0 0" />
      <geometry>
        <box size="0.06 0.035 0.26" />
      </geometry>
    </collision>
  </link>
  <joint name="FR_knee_joint" type="revolute">
    <origin
      xyz="0 0 -0.26"
      rpy="0 0 0" />
    <parent
      link="FR_hip_link" />
    <child
      link="FR_knee_link" />
    <axis
      xyz="0 1 0" />
    <limit
      lower="-2.6965"
      upper="-0.9163"
      effort="150"
      velocity="21" />
  </joint>
  <link name="FR_knee_link">
    <inertial>
      <origin
        xyz="0.017829 -1.577E-05 -0.099213"
        rpy="0 0 0" />
      <mass
        value="0.314" />
      <inertia
        ixx="0.003733"
        ixy="-0.000000087"
        ixz="-0.0006"
        iyy="0.003882"
        iyz="0.000000838"
        izz="0.000177" />
    </inertial>
    <visual>
      <origin
        xyz="0 0 0"
        rpy="0 0 0" />
      <geometry>
        <mesh
          filename="package://galileo_mini_description/meshes/FR_knee_link.STL" />
      </geometry>
      <material
        name="">
        <color
          rgba="0.75294 0.75294 0.75294 1" />
      </material>
    </visual>
    <collision>
      <origin
        xyz="0.0164695 0 -0.13"
        rpy="0 -0.17453 0" />
      <geometry>
        <box size="0.05 0.03 0.23" />
      </geometry>
    </collision>
  </link>
  <joint name="FR_foot_joint" type="fixed">
    <origin
      xyz="0.032939 0 -0.26149"
      rpy="0 0 0" />
    <parent
      link="FR_knee_link" />
    <child
      link="FR_foot_link" />
    <axis
      xyz="0 0 0" />
  </joint>
  <link name="FR_foot_link">
    <inertial>
      <origin
        xyz="0 0 0"
        rpy="0 0 0" />
      <mass
        value="0.00020487" />
      <inertia
        ixx="1.096E-09"
        ixy="0"
        ixz="1.7152E-40"
        iyy="1.096E-09"
        iyz="0"
        izz="1.096E-09" />
    </inertial>
    <visual>
      <origin
        xyz="0 0 0"
        rpy="0 0 0" />
      <geometry>
        <sphere radius="0.03" />
      </geometry>
      <material
        name="">
        <color
          rgba="1 1 1 1" />
      </material>
    </visual>
    <collision>
      <origin
        xyz="0 0 0"
        rpy="0 0 0" />
      <geometry>
        <sphere radius="0.03" />
      </geometry>
    </collision>
  </link>

  <joint name="HR_abd_joint" type="revolute">
    <origin
      xyz="-0.2015 -0.08 0"
      rpy="0 0 0" />
    <parent
      link="base_link" />
    <child
      link="HR_abd_link" />
    <axis
      xyz="1 0 0" />
    <limit
      lower="-0.80285"
      upper="0.80285"
      effort="100"
      velocity="21" />
  </joint>
  <link name="HR_abd_link">
    <inertial>
      <origin
        xyz="-0.067556 -0.0095934 -1.7463E-05"
        rpy="0 0 0" />
      <mass
        value="2.86" />
      <inertia
        ixx="0.004372"
        ixy="0.000364"
        ixz="-0.000106"
        iyy="0.007471"
        iyz="-0.000038"
        izz="0.006768" />
    </inertial>
    <visual>
      <origin
        xyz="0 0 0"
        rpy="0 0 0" />
      <geometry>
        <mesh
          filename="package://galileo_mini_description/meshes/HR_abd_link.STL" />
      </geometry>
      <material
        name="">
        <color
          rgba="0.75294 0.75294 0.75294 1" />
      </material>
    </visual>
    <collision>
      <origin
        xyz="-0.1 -0.03325 0"
        rpy="1.5707963 0 0" />
      <geometry>
        <cylinder radius="0.06" length="0.1065" />
      </geometry>
    </collision>
  </link>
  <joint name="HR_hip_joint" type="revolute">
    <origin
      xyz="-0.1 -0.10685 0"
      rpy="0 0 0" />
    <parent
      link="HR_abd_link" />
    <child
      link="HR_hip_link" />
    <axis
      xyz="0 1 0" />
    <limit
      lower="-4.1888"
      upper="1.0472"
      effort="100"
      velocity="21" />
  </joint>
  <link name="HR_hip_link">
    <inertial>
      <origin
        xyz="-0.0098055 0.020667 -0.067167"
        rpy="0 0 0" />
      <mass
        value="2.6" />
      <inertia
        ixx="0.017144"
        ixy="0.000198"
        ixz="0.001067"
        iyy="0.016508"
        iyz="0.002833"
        izz="0.002907" />
    </inertial>
    <visual>
      <origin
        xyz="0 0 0"
        rpy="0 0 0" />
      <geometry>
        <mesh
          filename="package://galileo_mini_description/meshes/HR_hip_link.STL" />
      </geometry>
      <material
        name="">
        <color
          rgba="0.75294 0.75294 0.75294 1" />
      </material>
    </visual>
    <collision>
      <origin
        xyz="-0.025 0 -0.08"
        rpy="0 0 0" />
      <geometry>
        <box size="0.06 0.035 0.26" />
      </geometry>
    </collision>
  </link>
  <joint name="HR_knee_joint" type="revolute">
    <origin
      xyz="0 0 -0.26"
      rpy="0 0 0" />
    <parent
      link="HR_hip_link" />
    <child
      link="HR_knee_link" />
    <axis
      xyz="0 1 0" />
    <limit
      lower="-2.6965"
      upper="-0.9163"
      effort="150"
      velocity="21" />
  </joint>
  <link name="HR_knee_link">
    <inertial>
      <origin
        xyz="0.017829 -1.577E-05 -0.099213"
        rpy="0 0 0" />
      <mass
        value="0.314" />
      <inertia
        ixx="0.003733"
        ixy="-0.000000087"
        ixz="-0.0006"
        iyy="0.003882"
        iyz="0.000000838"
        izz="0.000177" />
    </inertial>
    <visual>
      <origin
        xyz="0 0 0"
        rpy="0 0 0" />
      <geometry>
        <mesh
          filename="package://galileo_mini_description/meshes/HR_knee_link.STL" />
      </geometry>
      <material
        name="">
        <color
          rgba="0.75294 0.75294 0.75294 1" />
      </material>
    </visual>
    <collision>
      <origin
        xyz="0.0164695 0 -0.13"
        rpy="0 -0.17453 0" />
      <geometry>
        <box size="0.05 0.03 0.23" />
      </geometry>
    </collision>
  </link>
  <joint name="RR_foot_joint" type="fixed">
    <origin
      xyz="0.032939 0 -0.26149"
      rpy="0 0 0" />
    <parent
      link="HR_knee_link" />
    <child
      link="HR_foot_link" />
    <axis
      xyz="0 0 0" />
  </joint>
  <link name="HR_foot_link">
    <inertial>
      <origin
        xyz="0 0 0"
        rpy="0 0 0" />
      <mass
        value="0.000204873572147578" />
      <inertia
        ixx="1.09600066619755E-09"
        ixy="0"
        ixz="5.28443143791483E-42"
        iyy="1.09600066619755E-09"
        iyz="0"
        izz="1.09600066619755E-09" />
    </inertial>
    <visual>
      <origin
        xyz="0 0 0"
        rpy="0 0 0" />
      <geometry>
        <sphere radius="0.03" />
      </geometry>
      <material
        name="">
        <color
          rgba="1 1 1 1" />
      </material>
    </visual>
    <collision>
      <origin
        xyz="0 0 0"
        rpy="0 0 0" />
      <geometry>
        <sphere radius="0.03" />
      </geometry>
    </collision>
  </link>

  <joint name="HL_abd_joint" type="revolute">
    <origin
      xyz="-0.2015 0.08 0"
      rpy="0 0 0" />
    <parent
      link="base_link" />
    <child
      link="HL_abd_link" />
    <axis
      xyz="1 0 0" />
    <limit
      lower="-0.80285"
      upper="0.80285"
      effort="100"
      velocity="21" />
  </joint>
  <link name="HL_abd_link">
    <inertial>
      <origin
        xyz="-0.06741 0.0095934 7.3103E-05"
        rpy="0 0 0" />
      <mass
        value="2.86" />
      <inertia
        ixx="0.004372"
        ixy="0.000364"
        ixz="-0.000106"
        iyy="0.007471"
        iyz="-0.000038"
        izz="0.006768" />
    </inertial>
    <visual>
      <origin
        xyz="0 0 0"
        rpy="0 0 0" />
      <geometry>
        <mesh
          filename="package://galileo_mini_description/meshes/HL_abd_link.STL" />
      </geometry>
      <material
        name="">
        <color
          rgba="0.75294 0.75294 0.75294 1" />
      </material>
    </visual>
    <collision>
      <origin
        xyz="-0.1 0.03325 0"
        rpy="1.5707963 0 0" />
      <geometry>
        <cylinder radius="0.06" length="0.1065" />
      </geometry>
    </collision>
  </link>
  <joint name="HL_hip_joint" type="revolute">
    <origin
      xyz="-0.1 0.1065 0"
      rpy="0 0 0" />
    <parent
      link="HL_abd_link" />
    <child
      link="HL_hip_link" />
    <axis
      xyz="0 1 0" />
    <limit
      lower="-4.1888"
      upper="1.0472"
      effort="100"
      velocity="21" />
  </joint>
  <link name="HL_hip_link">
    <inertial>
      <origin
        xyz="-0.0090357 -0.0065295 -0.0688"
        rpy="0 0 0" />
      <mass
        value="2.6" />
      <inertia
        ixx="0.016848"
        ixy="-0.000310"
        ixz="0.001116"
        iyy="0.016749"
        iyz="-0.002270"
        izz="0.002088" />
    </inertial>
    <visual>
      <origin
        xyz="0 0 0"
        rpy="0 0 0" />
      <geometry>
        <mesh
          filename="package://galileo_mini_description/meshes/HL_hip_link.STL" />
      </geometry>
      <material
        name="">
        <color
          rgba="0.75294 0.75294 0.75294 1" />
      </material>
    </visual>
    <collision>
      <origin
        xyz="-0.025 0 -0.08"
        rpy="0 0 0" />
      <geometry>
        <box size="0.06 0.035 0.26" />
      </geometry>
    </collision>
  </link>
  <joint name="HL_knee_joint" type="revolute">
    <origin
      xyz="6.3209E-05 0 -0.26"
      rpy="0 0 0" />
    <parent
      link="HL_hip_link" />
    <child
      link="HL_knee_link" />
    <axis
      xyz="0 1 0" />
    <limit
      lower="-2.6965"
      upper="-0.9163"
      effort="150"
      velocity="21" />
  </joint>
  <link name="HL_knee_link">
    <inertial>
      <origin
        xyz="0.017829 -1.577E-05 -0.099213"
        rpy="0 0 0" />
      <mass
        value="0.314" />
      <inertia
        ixx="0.003733"
        ixy="-0.000000087"
        ixz="-0.0006"
        iyy="0.003882"
        iyz="0.000000838"
        izz="0.000177" />
    </inertial>
    <visual>
      <origin
        xyz="0 0 0"
        rpy="0 0 0" />
      <geometry>
        <mesh
          filename="package://galileo_mini_description/meshes/HL_knee_link.STL" />
      </geometry>
      <material
        name="">
        <color
          rgba="0.75294 0.75294 0.75294 1" />
      </material>
    </visual>
    <collision>
      <origin
        xyz="0.0164695 0 -0.13"
        rpy="0 -0.17453 0" />
      <geometry>
        <box size="0.05 0.03 0.23" />
      </geometry>
    </collision>
  </link>
  <joint name="HL_foot_link" type="fixed">
    <origin
      xyz="0.0329385085367515 0 -0.261492891464613"
      rpy="0 0 0" />
    <parent
      link="HL_knee_link" />
    <child
      link="HL_foot_link" />
    <axis
      xyz="0 0 0" />
  </joint>
  <link name="HL_foot_link">
    <inertial>
      <origin
        xyz="0 5.55111512312578E-17 0"
        rpy="0 0 0" />
      <mass
        value="0.000204873572147578" />
      <inertia
        ixx="1.09600066619755E-09"
        ixy="0"
        ixz="7.97487625425431E-42"
        iyy="1.09600066619755E-09"
        iyz="0"
        izz="1.09600066619755E-09" />
    </inertial>
    <visual>
      <origin
        xyz="0 0 0"
        rpy="0 0 0" />
      <geometry>
        <sphere radius="0.03" />
      </geometry>
      <material
        name="">
        <color
          rgba="1 1 1 1" />
      </material>
    </visual>
    <collision>
      <origin
        xyz="0 0 0"
        rpy="0 0 0" />
      <geometry>
        <sphere radius="0.03" />
      </geometry>
    </collision>
  </link>
</robot>